<?xml version="1.0"?>
<robot name="elevator">

  <!-- =========================
       Static elevator body
       ========================= -->
  <link name="cabin_link">
    <visual>
      <origin xyz="0 0 0" rpy="0 0 0"/>
      <geometry>
        <mesh filename="static_elevator.dae" scale="1 1 1"/>
      </geometry>
    </visual>

    <collision>
      <origin xyz="0 0 0" rpy="0 0 0"/>
      <geometry>
        <box size="4.2356 0.2952 3.2904"/>
      </geometry>
    </collision>

    <inertial>
      <origin xyz="0 0 0" rpy="0 0 0"/>
      <mass value="50.0"/>
      <inertia ixx="10" ixy="0" ixz="0" iyy="10" iyz="0" izz="10"/>
    </inertial>
  </link>

  <!-- =========================
       Door2 (moving)
       ========================= -->
  <link name="door2_link">
    <visual>
      <origin xyz="0 0 0" rpy="0 0 0"/>
      <geometry>
        <mesh filename="door2.dae" scale="1 1 1"/>
      </geometry>
    </visual>

    <collision>
      <origin xyz="0 0 0" rpy="0 0 0"/>
      <geometry>
        <box size="0.9537 0.1362 2.7992"/>
      </geometry>
    </collision>

    <inertial>
      <origin xyz="0 0 0" rpy="0 0 0"/>
      <mass value="5.0"/>
      <inertia ixx="0.5" ixy="0" ixz="0" iyy="0.5" iyz="0" izz="0.5"/>
    </inertial>
  </link>

  <joint name="door2_joint" type="prismatic">
    <parent link="cabin_link"/>
    <child link="door2_link"/>
    <origin xyz="0 0 0" rpy="0 0 0"/>

    <!-- slides along -X using negative limit -->
    <axis xyz="1 0 0"/>

    <limit lower="-0.5" upper="0.0" effort="200" velocity="0.5"/>
  </joint>

</robot>